I'm sorry, but an uncaught exception occurred.

While running game code:
  File "game/script.rpy", line 249, in script
    narration "victory"
Exception: Sayer 'narration' is not defined.

-- Full Traceback ------------------------------------------------------------

Full traceback:
  File "game/script.rpy", line 249, in script
    narration "victory"
  File "D:\2 - Cours\1 - année_n°1\Logiciel\renpy-8.1.3-sdk\renpy\ast.py", line 890, in execute
    who = eval_who(self.who, self.who_fast)
  File "D:\2 - Cours\1 - année_n°1\Logiciel\renpy-8.1.3-sdk\renpy\ast.py", line 783, in eval_who
    raise Exception("Sayer '%s' is not defined." % who)
Exception: Sayer 'narration' is not defined.

Windows-10-10.0.19045 AMD64
Ren'Py 8.1.3.23091805
Visual_Novel_2024 1.0
Tue Feb  6 16:05:30 2024
